audits/Q003/q003_non_parent_window_path_1000_1030_202601_v1/case_sample.csv
symbol,date,side,order_id,classification,first_add_row,first_trade_row,add_qty,active_trade_qty,immediate_trade_qty,add_events,trade_events,reconstructed_submit_qty
SH600000,20260105,B,473011,passive_only,3269,,100,0,0,1,0,100
SH600000,20260105,B,473150,passive_only,3270,,100,0,0,1,0,100
SH600000,20260105,B,473193,passive_only,3272,,100,0,0,1,0,100
SH600000,20260105,B,474203,trade_only_active,,3278,0,3000,0,0,4,3000
SH600000,20260105,B,474682,passive_only,3296,,100,0,0,1,0,100
SH600000,20260105,B,474725,passive_only,3297,,100,0,0,1,0,100
SH600000,20260105,B,474961,passive_only,3301,,100,0,0,1,0,100
SH600000,20260105,B,475523,passive_only,3306,,2000,0,0,1,0,2000
SH600000,20260105,B,478102,trade_only_active,,3316,0,4000,0,0,1,4000
SH600000,20260105,B,480890,trade_only_active,,3326,0,54400,0,0,12,54400
SH600000,20260105,B,481617,passive_only,3339,,600,0,0,1,0,600
SH600000,20260105,B,485172,passive_only,3346,,500,0,0,1,0,500
SH600000,20260105,B,485318,passive_only,3349,,300,0,0,1,0,300
SH600000,20260105,B,487968,trade_only_active,,3353,0,100,0,0,1,100
SH600000,20260105,B,488540,passive_only,3354,,100,0,0,1,0,100
SH600000,20260105,B,489593,passive_only,3357,,5000,0,0,1,0,5000
SH600000,20260105,B,493111,passive_only,3365,,2000,0,0,1,0,2000
SH600000,20260105,B,505570,trade_only_active,,3393,0,400,0,0,3,400
SH600000,20260105,B,507339,passive_only,3398,,300,0,0,1,0,300
SH600000,20260105,B,511341,passive_only,3405,,4600,0,0,1,0,4600
SH600000,20260105,B,514300,trade_only_active,,3410,0,2000,0,0,4,2000
SH600000,20260105,B,516329,trade_only_active,,3421,0,400,0,0,1,400
SH600000,20260105,B,517696,passive_only,3422,,2000,0,0,1,0,2000
SH600000,20260105,B,517818,passive_only,3423,,2000,0,0,1,0,2000
SH600000,20260105,B,517960,passive_only,3425,,2000,0,0,1,0,2000
SH600000,20260105,B,518027,passive_only,3426,,200,0,0,1,0,200
SH600000,20260105,B,518455,passive_only,3427,,2000,0,0,1,0,2000
SH600000,20260105,B,528251,passive_only,3445,,500,0,0,1,0,500
SH600000,20260105,B,528914,trade_only_active,,3448,0,500,0,0,2,500
SH600000,20260105,B,530715,trade_only_active,,3451,0,200,0,0,1,200
SH600000,20260105,B,534888,passive_only,3459,,2000,0,0,1,0,2000
SH600000,20260105,B,534895,passive_only,3460,,2000,0,0,1,0,2000
SH600000,20260105,B,534896,passive_only,3461,,2000,0,0,1,0,2000
SH600000,20260105,B,534897,passive_only,3462,,2000,0,0,1,0,2000
SH600000,20260105,B,534900,passive_only,3463,,2000,0,0,1,0,2000
SH600000,20260105,B,534910,passive_only,3464,,2000,0,0,1,0,2000
SH600000,20260105,B,534920,passive_only,3465,,2000,0,0,1,0,2000
SH600000,20260105,B,534934,passive_only,3466,,2000,0,0,1,0,2000
SH600000,20260105,B,534937,passive_only,3467,,2000,0,0,1,0,2000
SH600000,20260105,B,534944,passive_only,3468,,2000,0,0,1,0,2000
SH600000,20260105,B,535430,trade_only_active,,3471,0,300,0,0,2,300
SH600000,20260105,B,536344,trade_only_active,,3473,0,500,0,0,1,500
SH600000,20260105,B,537248,passive_only,3476,,300,0,0,1,0,300
SH600000,20260105,B,537250,passive_only,3477,,300,0,0,1,0,300
SH600000,20260105,B,537251,passive_only,3478,,300,0,0,1,0,300
SH600000,20260105,B,537254,passive_only,3479,,400,0,0,1,0,400
SH600000,20260105,B,537258,passive_only,3481,,200,0,0,1,0,200
SH600000,20260105,B,537260,passive_only,3482,,400,0,0,1,0,400
SH600000,20260105,B,537267,passive_only,3483,,300,0,0,1,0,300
SH600000,20260105,B,537275,passive_only,3485,,200,0,0,1,0,200
SH600000,20260105,B,537278,passive_only,3487,,200,0,0,1,0,200
SH600000,20260105,B,537280,passive_only,3489,,200,0,0,1,0,200
SH600000,20260105,B,537284,passive_only,3491,,200,0,0,1,0,200
SH600000,20260105,B,537291,passive_only,3493,,200,0,0,1,0,200
SH600000,20260105,B,537293,passive_only,3494,,400,0,0,1,0,400
SH600000,20260105,B,537294,passive_only,3495,,300,0,0,1,0,300
SH600000,20260105,B,537299,passive_only,3497,,200,0,0,1,0,200
SH600000,20260105,B,541933,trade_only_active,,3514,0,3300,0,0,2,3300
SH600000,20260105,B,546821,trade_only_active,,3538,0,400,0,0,1,400
SH600000,20260105,B,547957,trade_only_active,,3540,0,300,0,0,1,300
SH600000,20260105,B,548028,trade_only_active,,3541,0,200,0,0,1,200
SH600000,20260105,B,553353,passive_only,3551,,4000,0,0,1,0,4000
SH600000,20260105,B,555245,trade_only_active,,3556,0,400,0,0,2,400
SH600000,20260105,B,555338,passive_only,3558,,100,0,0,1,0,100
SH600000,20260105,B,555343,passive_only,3559,,100,0,0,1,0,100
SH600000,20260105,B,556564,trade_only_active,,3562,0,4600,0,0,7,4600
SH600000,20260105,B,559934,trade_only_active,,3578,0,1000,0,0,2,1000
SH600000,20260105,B,562252,passive_only,3583,,3400,0,0,1,0,3400
SH600000,20260105,B,563078,trade_only_active,,3585,0,700,0,0,1,700
SH600000,20260105,B,563934,passive_only,3590,,800,0,0,1,0,800
SH600000,20260105,B,577743,trade_only_active,,3690,0,500,0,0,1,500
SH600000,20260105,B,578103,trade_only_active,,3702,0,100,0,0,1,100
SH600000,20260105,B,580261,trade_only_active,,3708,0,100,0,0,1,100
SH600000,20260105,B,581654,trade_only_active,,3713,0,100,0,0,1,100
SH600000,20260105,B,583240,trade_only_active,,3725,0,600,0,0,2,600
SH600000,20260105,B,585280,trade_only_active,,3736,0,5000,0,0,3,5000
SH600000,20260105,B,586694,trade_only_active,,3743,0,100,0,0,1,100
SH600000,20260105,B,589153,trade_only_active,,3755,0,100,0,0,1,100
SH600000,20260105,B,590641,passive_only,3761,,800,0,0,1,0,800
SH600000,20260105,B,590929,trade_only_active,,3764,0,700,0,0,1,700
SH600000,20260105,B,591109,trade_only_active,,3765,0,600,0,0,1,600
SH600000,20260105,B,591292,trade_only_active,,3766,0,100,0,0,1,100
SH600000,20260105,B,592790,passive_only,3774,,2000,0,0,1,0,2000
SH600000,20260105,B,597941,trade_only_active,,3784,0,800,0,0,1,800
SH600000,20260105,B,600016,trade_only_active,,3789,0,400,0,0,2,400
SH600000,20260105,B,601308,passive_only,3792,,300,0,0,1,0,300
SH600000,20260105,B,601937,trade_only_active,,3793,0,200,0,0,1,200
SH600000,20260105,B,603528,passive_only,3803,,1000,0,0,1,0,1000
SH600000,20260105,B,606777,passive_only,3815,,100,0,0,1,0,100
SH600000,20260105,B,607387,passive_only,3816,,100,0,0,1,0,100
SH600000,20260105,B,608362,passive_only,3821,,300,0,0,1,0,300
SH600000,20260105,B,609958,passive_only,3825,,1000,0,0,1,0,1000
SH600000,20260105,B,611995,passive_only,3840,,2000,0,0,1,0,2000
SH600000,20260105,B,613259,passive_only,3852,,1000,0,0,1,0,1000
SH600000,20260105,B,615091,trade_only_active,,3862,0,300,0,0,1,300
SH600000,20260105,B,617367,passive_only,3870,,3000,0,0,1,0,3000
SH600000,20260105,B,617454,trade_only_active,,3871,0,6400,0,0,4,6400
SH600000,20260105,B,618903,trade_only_active,,3878,0,400,0,0,1,400
SH600000,20260105,B,619309,passive_only,3887,,100,0,0,1,0,100
SH600000,20260105,B,620773,trade_only_active,,3893,0,900,0,0,1,900
SH600000,20260105,B,621362,passive_only,3897,,10000,0,0,1,0,10000
SH600000,20260105,B,621574,passive_only,3900,,5700,0,0,1,0,5700
SH600000,20260105,B,625226,trade_only_active,,3913,0,600,0,0,2,600
SH600000,20260105,B,627164,trade_only_active,,3920,0,1000,0,0,3,1000
SH600000,20260105,B,628912,trade_only_active,,3930,0,100,0,0,1,100
SH600000,20260105,B,630011,trade_only_active,,3933,0,300,0,0,1,300
SH600000,20260105,B,631680,trade_only_active,,3938,0,1000,0,0,1,1000
SH600000,20260105,B,632306,trade_only_active,,3941,0,5100,0,0,6,5100
SH600000,20260105,B,635471,passive_only,3952,,500,0,0,1,0,500
SH600000,20260105,B,636243,trade_only_active,,3954,0,1400,0,0,2,1400
SH600000,20260105,B,639792,trade_only_active,,3967,0,300,0,0,2,300
SH600000,20260105,B,642285,trade_only_active,,3973,0,700,0,0,3,700
SH600000,20260105,B,643569,trade_only_active,,3978,0,400,0,0,1,400
SH600000,20260105,B,645644,passive_only,3981,,500,0,0,1,0,500
SH600000,20260105,B,647047,trade_only_active,,3988,0,100,0,0,1,100
SH600000,20260105,B,647499,trade_only_active,,3990,0,900,0,0,2,900
SH600000,20260105,B,647894,trade_only_active,,3995,0,400,0,0,1,400
SH600000,20260105,B,651542,trade_only_active,,3999,0,100,0,0,1,100
SH600000,20260105,B,653285,trade_only_active,,4004,0,1000,0,0,1,1000
SH600000,20260105,B,655834,trade_only_active,,4025,0,900,0,0,3,900
SH600000,20260105,B,656064,passive_only,4028,,400,0,0,1,0,400
